2021-02-11 13:20:47,065 ERROR: Exception on /reset_password_request [POST] [in /home/ashutosh.mahawar/.local/lib/python3.8/site-packages/flask/app.py:1891]
Traceback (most recent call last):
  File "/home/ashutosh.mahawar/.local/lib/python3.8/site-packages/flask/app.py", line 2447, in wsgi_app
    response = self.full_dispatch_request()
  File "/home/ashutosh.mahawar/.local/lib/python3.8/site-packages/flask/app.py", line 1952, in full_dispatch_request
    rv = self.handle_user_exception(e)
  File "/home/ashutosh.mahawar/.local/lib/python3.8/site-packages/flask/app.py", line 1821, in handle_user_exception
    reraise(exc_type, exc_value, tb)
  File "/home/ashutosh.mahawar/.local/lib/python3.8/site-packages/flask/_compat.py", line 39, in reraise
    raise value
  File "/home/ashutosh.mahawar/.local/lib/python3.8/site-packages/flask/app.py", line 1950, in full_dispatch_request
    rv = self.dispatch_request()
  File "/home/ashutosh.mahawar/.local/lib/python3.8/site-packages/flask/app.py", line 1936, in dispatch_request
    return self.view_functions[rule.endpoint](**req.view_args)
  File "/home/ashutosh.mahawar/flaskprojects/application1/app/routes.py", line 171, in reset_password_request
    send_password_reset_email(user)
  File "/home/ashutosh.mahawar/flaskprojects/application1/app/email.py", line 14, in send_password_reset_email
    send_email('[Application] Reset Your Password',
  File "/home/ashutosh.mahawar/flaskprojects/application1/app/email.py", line 10, in send_email
    mail.send(msg)
  File "/home/ashutosh.mahawar/.local/lib/python3.8/site-packages/flask_mail.py", line 491, in send
    with self.connect() as connection:
  File "/home/ashutosh.mahawar/.local/lib/python3.8/site-packages/flask_mail.py", line 144, in __enter__
    self.host = self.configure_host()
  File "/home/ashutosh.mahawar/.local/lib/python3.8/site-packages/flask_mail.py", line 158, in configure_host
    host = smtplib.SMTP(self.mail.server, self.mail.port)
  File "/usr/lib/python3.8/smtplib.py", line 253, in __init__
    (code, msg) = self.connect(host, port)
  File "/usr/lib/python3.8/smtplib.py", line 339, in connect
    self.sock = self._get_socket(host, port, self.timeout)
  File "/usr/lib/python3.8/smtplib.py", line 308, in _get_socket
    return socket.create_connection((host, port), timeout,
  File "/usr/lib/python3.8/socket.py", line 808, in create_connection
    raise err
  File "/usr/lib/python3.8/socket.py", line 796, in create_connection
    sock.connect(sa)
OSError: [Errno 101] Network is unreachable
2021-02-11 13:23:50,023 INFO: Application startup [in /home/ashutosh.mahawar/flaskprojects/application1/app/__init__.py:49]
2021-02-11 13:24:13,162 ERROR: Exception on /reset_password_request [POST] [in /home/ashutosh.mahawar/.local/lib/python3.8/site-packages/flask/app.py:1891]
Traceback (most recent call last):
  File "/home/ashutosh.mahawar/.local/lib/python3.8/site-packages/flask/app.py", line 2447, in wsgi_app
    response = self.full_dispatch_request()
  File "/home/ashutosh.mahawar/.local/lib/python3.8/site-packages/flask/app.py", line 1952, in full_dispatch_request
    rv = self.handle_user_exception(e)
  File "/home/ashutosh.mahawar/.local/lib/python3.8/site-packages/flask/app.py", line 1821, in handle_user_exception
    reraise(exc_type, exc_value, tb)
  File "/home/ashutosh.mahawar/.local/lib/python3.8/site-packages/flask/_compat.py", line 39, in reraise
    raise value
  File "/home/ashutosh.mahawar/.local/lib/python3.8/site-packages/flask/app.py", line 1950, in full_dispatch_request
    rv = self.dispatch_request()
  File "/home/ashutosh.mahawar/.local/lib/python3.8/site-packages/flask/app.py", line 1936, in dispatch_request
    return self.view_functions[rule.endpoint](**req.view_args)
  File "/home/ashutosh.mahawar/flaskprojects/application1/app/routes.py", line 171, in reset_password_request
    send_password_reset_email(user)
  File "/home/ashutosh.mahawar/flaskprojects/application1/app/email.py", line 14, in send_password_reset_email
    send_email('[Application] Reset Your Password',
  File "/home/ashutosh.mahawar/flaskprojects/application1/app/email.py", line 10, in send_email
    mail.send(msg)
  File "/home/ashutosh.mahawar/.local/lib/python3.8/site-packages/flask_mail.py", line 491, in send
    with self.connect() as connection:
  File "/home/ashutosh.mahawar/.local/lib/python3.8/site-packages/flask_mail.py", line 144, in __enter__
    self.host = self.configure_host()
  File "/home/ashutosh.mahawar/.local/lib/python3.8/site-packages/flask_mail.py", line 165, in configure_host
    host.login(self.mail.username, self.mail.password)
  File "/usr/lib/python3.8/smtplib.py", line 734, in login
    raise last_exception
  File "/usr/lib/python3.8/smtplib.py", line 723, in login
    (code, resp) = self.auth(
  File "/usr/lib/python3.8/smtplib.py", line 646, in auth
    raise SMTPAuthenticationError(code, resp)
smtplib.SMTPAuthenticationError: (535, b'5.7.8 Username and Password not accepted. Learn more at\n5.7.8  https://support.google.com/mail/?p=BadCredentials s22sm4531318pfe.133 - gsmtp')
2021-02-11 13:30:52,216 INFO: Application startup [in /home/ashutosh.mahawar/flaskprojects/application1/app/__init__.py:49]
2021-02-11 13:31:12,374 ERROR: Exception on /reset_password_request [POST] [in /home/ashutosh.mahawar/.local/lib/python3.8/site-packages/flask/app.py:1891]
Traceback (most recent call last):
  File "/home/ashutosh.mahawar/.local/lib/python3.8/site-packages/flask/app.py", line 2447, in wsgi_app
    response = self.full_dispatch_request()
  File "/home/ashutosh.mahawar/.local/lib/python3.8/site-packages/flask/app.py", line 1952, in full_dispatch_request
    rv = self.handle_user_exception(e)
  File "/home/ashutosh.mahawar/.local/lib/python3.8/site-packages/flask/app.py", line 1821, in handle_user_exception
    reraise(exc_type, exc_value, tb)
  File "/home/ashutosh.mahawar/.local/lib/python3.8/site-packages/flask/_compat.py", line 39, in reraise
    raise value
  File "/home/ashutosh.mahawar/.local/lib/python3.8/site-packages/flask/app.py", line 1950, in full_dispatch_request
    rv = self.dispatch_request()
  File "/home/ashutosh.mahawar/.local/lib/python3.8/site-packages/flask/app.py", line 1936, in dispatch_request
    return self.view_functions[rule.endpoint](**req.view_args)
  File "/home/ashutosh.mahawar/flaskprojects/application1/app/routes.py", line 171, in reset_password_request
    send_password_reset_email(user)
  File "/home/ashutosh.mahawar/flaskprojects/application1/app/email.py", line 14, in send_password_reset_email
    send_email('[Application] Reset Your Password',
  File "/home/ashutosh.mahawar/flaskprojects/application1/app/email.py", line 10, in send_email
    mail.send(msg)
  File "/home/ashutosh.mahawar/.local/lib/python3.8/site-packages/flask_mail.py", line 491, in send
    with self.connect() as connection:
  File "/home/ashutosh.mahawar/.local/lib/python3.8/site-packages/flask_mail.py", line 144, in __enter__
    self.host = self.configure_host()
  File "/home/ashutosh.mahawar/.local/lib/python3.8/site-packages/flask_mail.py", line 165, in configure_host
    host.login(self.mail.username, self.mail.password)
  File "/usr/lib/python3.8/smtplib.py", line 734, in login
    raise last_exception
  File "/usr/lib/python3.8/smtplib.py", line 723, in login
    (code, resp) = self.auth(
  File "/usr/lib/python3.8/smtplib.py", line 646, in auth
    raise SMTPAuthenticationError(code, resp)
smtplib.SMTPAuthenticationError: (535, b'5.7.8 Username and Password not accepted. Learn more at\n5.7.8  https://support.google.com/mail/?p=BadCredentials f13sm6657129pjj.1 - gsmtp')
2021-02-11 13:33:53,098 INFO: Application startup [in /home/ashutosh.mahawar/flaskprojects/application1/app/__init__.py:49]
2021-02-11 13:34:02,395 ERROR: Exception on /reset_password_request [POST] [in /home/ashutosh.mahawar/.local/lib/python3.8/site-packages/flask/app.py:1891]
Traceback (most recent call last):
  File "/home/ashutosh.mahawar/.local/lib/python3.8/site-packages/flask/app.py", line 2447, in wsgi_app
    response = self.full_dispatch_request()
  File "/home/ashutosh.mahawar/.local/lib/python3.8/site-packages/flask/app.py", line 1952, in full_dispatch_request
    rv = self.handle_user_exception(e)
  File "/home/ashutosh.mahawar/.local/lib/python3.8/site-packages/flask/app.py", line 1821, in handle_user_exception
    reraise(exc_type, exc_value, tb)
  File "/home/ashutosh.mahawar/.local/lib/python3.8/site-packages/flask/_compat.py", line 39, in reraise
    raise value
  File "/home/ashutosh.mahawar/.local/lib/python3.8/site-packages/flask/app.py", line 1950, in full_dispatch_request
    rv = self.dispatch_request()
  File "/home/ashutosh.mahawar/.local/lib/python3.8/site-packages/flask/app.py", line 1936, in dispatch_request
    return self.view_functions[rule.endpoint](**req.view_args)
  File "/home/ashutosh.mahawar/flaskprojects/application1/app/routes.py", line 171, in reset_password_request
    send_password_reset_email(user)
  File "/home/ashutosh.mahawar/flaskprojects/application1/app/email.py", line 14, in send_password_reset_email
    send_email('[Application] Reset Your Password',
  File "/home/ashutosh.mahawar/flaskprojects/application1/app/email.py", line 10, in send_email
    mail.send(msg)
  File "/home/ashutosh.mahawar/.local/lib/python3.8/site-packages/flask_mail.py", line 491, in send
    with self.connect() as connection:
  File "/home/ashutosh.mahawar/.local/lib/python3.8/site-packages/flask_mail.py", line 144, in __enter__
    self.host = self.configure_host()
  File "/home/ashutosh.mahawar/.local/lib/python3.8/site-packages/flask_mail.py", line 165, in configure_host
    host.login(self.mail.username, self.mail.password)
  File "/usr/lib/python3.8/smtplib.py", line 734, in login
    raise last_exception
  File "/usr/lib/python3.8/smtplib.py", line 723, in login
    (code, resp) = self.auth(
  File "/usr/lib/python3.8/smtplib.py", line 646, in auth
    raise SMTPAuthenticationError(code, resp)
smtplib.SMTPAuthenticationError: (535, b'5.7.8 Username and Password not accepted. Learn more at\n5.7.8  https://support.google.com/mail/?p=BadCredentials x17sm4396729pfq.132 - gsmtp')
