2021-02-11 13:36:30,488 INFO: Application startup [in /home/ashutosh.mahawar/flaskprojects/application1/app/__init__.py:49]
2021-02-11 13:36:51,340 ERROR: Exception on /reset_password_request [POST] [in /home/ashutosh.mahawar/.local/lib/python3.8/site-packages/flask/app.py:1891]
Traceback (most recent call last):
  File "/home/ashutosh.mahawar/.local/lib/python3.8/site-packages/flask/app.py", line 2447, in wsgi_app
    response = self.full_dispatch_request()
  File "/home/ashutosh.mahawar/.local/lib/python3.8/site-packages/flask/app.py", line 1952, in full_dispatch_request
    rv = self.handle_user_exception(e)
  File "/home/ashutosh.mahawar/.local/lib/python3.8/site-packages/flask/app.py", line 1821, in handle_user_exception
    reraise(exc_type, exc_value, tb)
  File "/home/ashutosh.mahawar/.local/lib/python3.8/site-packages/flask/_compat.py", line 39, in reraise
    raise value
  File "/home/ashutosh.mahawar/.local/lib/python3.8/site-packages/flask/app.py", line 1950, in full_dispatch_request
    rv = self.dispatch_request()
  File "/home/ashutosh.mahawar/.local/lib/python3.8/site-packages/flask/app.py", line 1936, in dispatch_request
    return self.view_functions[rule.endpoint](**req.view_args)
  File "/home/ashutosh.mahawar/flaskprojects/application1/app/routes.py", line 171, in reset_password_request
    send_password_reset_email(user)
  File "/home/ashutosh.mahawar/flaskprojects/application1/app/email.py", line 14, in send_password_reset_email
    send_email('[Application] Reset Your Password',
  File "/home/ashutosh.mahawar/flaskprojects/application1/app/email.py", line 10, in send_email
    mail.send(msg)
  File "/home/ashutosh.mahawar/.local/lib/python3.8/site-packages/flask_mail.py", line 491, in send
    with self.connect() as connection:
  File "/home/ashutosh.mahawar/.local/lib/python3.8/site-packages/flask_mail.py", line 144, in __enter__
    self.host = self.configure_host()
  File "/home/ashutosh.mahawar/.local/lib/python3.8/site-packages/flask_mail.py", line 165, in configure_host
    host.login(self.mail.username, self.mail.password)
  File "/usr/lib/python3.8/smtplib.py", line 734, in login
    raise last_exception
  File "/usr/lib/python3.8/smtplib.py", line 723, in login
    (code, resp) = self.auth(
  File "/usr/lib/python3.8/smtplib.py", line 646, in auth
    raise SMTPAuthenticationError(code, resp)
smtplib.SMTPAuthenticationError: (535, b'5.7.8 Username and Password not accepted. Learn more at\n5.7.8  https://support.google.com/mail/?p=BadCredentials q188sm4561458pfb.8 - gsmtp')
2021-02-11 13:43:46,544 INFO: Application startup [in /home/ashutosh.mahawar/flaskprojects/application1/app/__init__.py:49]
2021-02-11 13:44:03,232 ERROR: Exception on /reset_password_request [POST] [in /home/ashutosh.mahawar/.local/lib/python3.8/site-packages/flask/app.py:1891]
Traceback (most recent call last):
  File "/home/ashutosh.mahawar/.local/lib/python3.8/site-packages/flask/app.py", line 2447, in wsgi_app
    response = self.full_dispatch_request()
  File "/home/ashutosh.mahawar/.local/lib/python3.8/site-packages/flask/app.py", line 1952, in full_dispatch_request
    rv = self.handle_user_exception(e)
  File "/home/ashutosh.mahawar/.local/lib/python3.8/site-packages/flask/app.py", line 1821, in handle_user_exception
    reraise(exc_type, exc_value, tb)
  File "/home/ashutosh.mahawar/.local/lib/python3.8/site-packages/flask/_compat.py", line 39, in reraise
    raise value
  File "/home/ashutosh.mahawar/.local/lib/python3.8/site-packages/flask/app.py", line 1950, in full_dispatch_request
    rv = self.dispatch_request()
  File "/home/ashutosh.mahawar/.local/lib/python3.8/site-packages/flask/app.py", line 1936, in dispatch_request
    return self.view_functions[rule.endpoint](**req.view_args)
  File "/home/ashutosh.mahawar/flaskprojects/application1/app/routes.py", line 171, in reset_password_request
    send_password_reset_email(user)
  File "/home/ashutosh.mahawar/flaskprojects/application1/app/email.py", line 14, in send_password_reset_email
    send_email('[Application] Reset Your Password',
  File "/home/ashutosh.mahawar/flaskprojects/application1/app/email.py", line 10, in send_email
    mail.send(msg)
  File "/home/ashutosh.mahawar/.local/lib/python3.8/site-packages/flask_mail.py", line 491, in send
    with self.connect() as connection:
  File "/home/ashutosh.mahawar/.local/lib/python3.8/site-packages/flask_mail.py", line 144, in __enter__
    self.host = self.configure_host()
  File "/home/ashutosh.mahawar/.local/lib/python3.8/site-packages/flask_mail.py", line 165, in configure_host
    host.login(self.mail.username, self.mail.password)
  File "/usr/lib/python3.8/smtplib.py", line 734, in login
    raise last_exception
  File "/usr/lib/python3.8/smtplib.py", line 723, in login
    (code, resp) = self.auth(
  File "/usr/lib/python3.8/smtplib.py", line 646, in auth
    raise SMTPAuthenticationError(code, resp)
smtplib.SMTPAuthenticationError: (535, b'5.7.8 Username and Password not accepted. Learn more at\n5.7.8  https://support.google.com/mail/?p=BadCredentials z15sm4439898pjz.41 - gsmtp')
2021-02-18 11:16:58,711 INFO: Application startup [in /home/ashutosh.mahawar/flaskprojects/application1/app/__init__.py:49]
2021-02-18 11:17:57,462 ERROR: Exception on /reset_password_request [POST] [in /home/ashutosh.mahawar/.local/lib/python3.8/site-packages/flask/app.py:1891]
Traceback (most recent call last):
  File "/home/ashutosh.mahawar/.local/lib/python3.8/site-packages/flask/app.py", line 2447, in wsgi_app
    response = self.full_dispatch_request()
  File "/home/ashutosh.mahawar/.local/lib/python3.8/site-packages/flask/app.py", line 1952, in full_dispatch_request
    rv = self.handle_user_exception(e)
  File "/home/ashutosh.mahawar/.local/lib/python3.8/site-packages/flask/app.py", line 1821, in handle_user_exception
    reraise(exc_type, exc_value, tb)
  File "/home/ashutosh.mahawar/.local/lib/python3.8/site-packages/flask/_compat.py", line 39, in reraise
    raise value
  File "/home/ashutosh.mahawar/.local/lib/python3.8/site-packages/flask/app.py", line 1950, in full_dispatch_request
    rv = self.dispatch_request()
  File "/home/ashutosh.mahawar/.local/lib/python3.8/site-packages/flask/app.py", line 1936, in dispatch_request
    return self.view_functions[rule.endpoint](**req.view_args)
  File "/home/ashutosh.mahawar/flaskprojects/application1/app/routes.py", line 171, in reset_password_request
    send_password_reset_email(user)
  File "/home/ashutosh.mahawar/flaskprojects/application1/app/email.py", line 14, in send_password_reset_email
    send_email('[Application] Reset Your Password',
  File "/home/ashutosh.mahawar/flaskprojects/application1/app/email.py", line 10, in send_email
    mail.send(msg)
  File "/home/ashutosh.mahawar/.local/lib/python3.8/site-packages/flask_mail.py", line 491, in send
    with self.connect() as connection:
  File "/home/ashutosh.mahawar/.local/lib/python3.8/site-packages/flask_mail.py", line 144, in __enter__
    self.host = self.configure_host()
  File "/home/ashutosh.mahawar/.local/lib/python3.8/site-packages/flask_mail.py", line 165, in configure_host
    host.login(self.mail.username, self.mail.password)
  File "/usr/lib/python3.8/smtplib.py", line 734, in login
    raise last_exception
  File "/usr/lib/python3.8/smtplib.py", line 723, in login
    (code, resp) = self.auth(
  File "/usr/lib/python3.8/smtplib.py", line 646, in auth
    raise SMTPAuthenticationError(code, resp)
smtplib.SMTPAuthenticationError: (535, b'5.7.8 Username and Password not accepted. Learn more at\n5.7.8  https://support.google.com/mail/?p=BadCredentials o6sm3750176pfb.9 - gsmtp')
2021-02-18 11:34:39,298 INFO: Application startup [in /home/ashutosh.mahawar/flaskprojects/application1/app/__init__.py:49]
2021-02-18 11:34:51,651 ERROR: Exception on /reset_password_request [POST] [in /home/ashutosh.mahawar/.local/lib/python3.8/site-packages/flask/app.py:1891]
Traceback (most recent call last):
  File "/home/ashutosh.mahawar/.local/lib/python3.8/site-packages/flask/app.py", line 2447, in wsgi_app
    response = self.full_dispatch_request()
  File "/home/ashutosh.mahawar/.local/lib/python3.8/site-packages/flask/app.py", line 1952, in full_dispatch_request
    rv = self.handle_user_exception(e)
  File "/home/ashutosh.mahawar/.local/lib/python3.8/site-packages/flask/app.py", line 1821, in handle_user_exception
    reraise(exc_type, exc_value, tb)
  File "/home/ashutosh.mahawar/.local/lib/python3.8/site-packages/flask/_compat.py", line 39, in reraise
    raise value
  File "/home/ashutosh.mahawar/.local/lib/python3.8/site-packages/flask/app.py", line 1950, in full_dispatch_request
    rv = self.dispatch_request()
  File "/home/ashutosh.mahawar/.local/lib/python3.8/site-packages/flask/app.py", line 1936, in dispatch_request
    return self.view_functions[rule.endpoint](**req.view_args)
  File "/home/ashutosh.mahawar/flaskprojects/application1/app/routes.py", line 171, in reset_password_request
    send_password_reset_email(user)
  File "/home/ashutosh.mahawar/flaskprojects/application1/app/email.py", line 14, in send_password_reset_email
    send_email('[Application] Reset Your Password',
  File "/home/ashutosh.mahawar/flaskprojects/application1/app/email.py", line 10, in send_email
    mail.send(msg)
  File "/home/ashutosh.mahawar/.local/lib/python3.8/site-packages/flask_mail.py", line 491, in send
    with self.connect() as connection:
  File "/home/ashutosh.mahawar/.local/lib/python3.8/site-packages/flask_mail.py", line 144, in __enter__
    self.host = self.configure_host()
  File "/home/ashutosh.mahawar/.local/lib/python3.8/site-packages/flask_mail.py", line 165, in configure_host
    host.login(self.mail.username, self.mail.password)
  File "/usr/lib/python3.8/smtplib.py", line 734, in login
    raise last_exception
  File "/usr/lib/python3.8/smtplib.py", line 723, in login
    (code, resp) = self.auth(
  File "/usr/lib/python3.8/smtplib.py", line 646, in auth
    raise SMTPAuthenticationError(code, resp)
smtplib.SMTPAuthenticationError: (535, b'5.7.8 Username and Password not accepted. Learn more at\n5.7.8  https://support.google.com/mail/?p=BadCredentials 134sm4566519pfc.113 - gsmtp')
