2021-02-08 18:20:59,437 ERROR: Exception on /logout [GET] [in /home/ashutosh.mahawar/.local/lib/python3.8/site-packages/flask/app.py:1891]
Traceback (most recent call last):
  File "/home/ashutosh.mahawar/.local/lib/python3.8/site-packages/sqlalchemy/engine/base.py", line 2336, in _wrap_pool_connect
    return fn()
  File "/home/ashutosh.mahawar/.local/lib/python3.8/site-packages/sqlalchemy/pool/base.py", line 364, in connect
    return _ConnectionFairy._checkout(self)
  File "/home/ashutosh.mahawar/.local/lib/python3.8/site-packages/sqlalchemy/pool/base.py", line 778, in _checkout
    fairy = _ConnectionRecord.checkout(pool)
  File "/home/ashutosh.mahawar/.local/lib/python3.8/site-packages/sqlalchemy/pool/base.py", line 495, in checkout
    rec = pool._do_get()
  File "/home/ashutosh.mahawar/.local/lib/python3.8/site-packages/sqlalchemy/pool/impl.py", line 140, in _do_get
    self._dec_overflow()
  File "/home/ashutosh.mahawar/.local/lib/python3.8/site-packages/sqlalchemy/util/langhelpers.py", line 68, in __exit__
    compat.raise_(
  File "/home/ashutosh.mahawar/.local/lib/python3.8/site-packages/sqlalchemy/util/compat.py", line 182, in raise_
    raise exception
  File "/home/ashutosh.mahawar/.local/lib/python3.8/site-packages/sqlalchemy/pool/impl.py", line 137, in _do_get
    return self._create_connection()
  File "/home/ashutosh.mahawar/.local/lib/python3.8/site-packages/sqlalchemy/pool/base.py", line 309, in _create_connection
    return _ConnectionRecord(self)
  File "/home/ashutosh.mahawar/.local/lib/python3.8/site-packages/sqlalchemy/pool/base.py", line 440, in __init__
    self.__connect(first_connect_check=True)
  File "/home/ashutosh.mahawar/.local/lib/python3.8/site-packages/sqlalchemy/pool/base.py", line 661, in __connect
    pool.logger.debug("Error on connect(): %s", e)
  File "/home/ashutosh.mahawar/.local/lib/python3.8/site-packages/sqlalchemy/util/langhelpers.py", line 68, in __exit__
    compat.raise_(
  File "/home/ashutosh.mahawar/.local/lib/python3.8/site-packages/sqlalchemy/util/compat.py", line 182, in raise_
    raise exception
  File "/home/ashutosh.mahawar/.local/lib/python3.8/site-packages/sqlalchemy/pool/base.py", line 656, in __connect
    connection = pool._invoke_creator(self)
  File "/home/ashutosh.mahawar/.local/lib/python3.8/site-packages/sqlalchemy/engine/strategies.py", line 114, in connect
    return dialect.connect(*cargs, **cparams)
  File "/home/ashutosh.mahawar/.local/lib/python3.8/site-packages/sqlalchemy/engine/default.py", line 508, in connect
    return self.dbapi.connect(*cargs, **cparams)
  File "/home/ashutosh.mahawar/.local/lib/python3.8/site-packages/psycopg2/__init__.py", line 127, in connect
    conn = _connect(dsn, connection_factory=connection_factory, **kwasync)
psycopg2.OperationalError: FATAL:  password authentication failed for user "postgres"
FATAL:  password authentication failed for user "postgres"


The above exception was the direct cause of the following exception:

Traceback (most recent call last):
  File "/home/ashutosh.mahawar/.local/lib/python3.8/site-packages/flask/app.py", line 2447, in wsgi_app
    response = self.full_dispatch_request()
  File "/home/ashutosh.mahawar/.local/lib/python3.8/site-packages/flask/app.py", line 1952, in full_dispatch_request
    rv = self.handle_user_exception(e)
  File "/home/ashutosh.mahawar/.local/lib/python3.8/site-packages/flask/app.py", line 1821, in handle_user_exception
    reraise(exc_type, exc_value, tb)
  File "/home/ashutosh.mahawar/.local/lib/python3.8/site-packages/flask/_compat.py", line 39, in reraise
    raise value
  File "/home/ashutosh.mahawar/.local/lib/python3.8/site-packages/flask/app.py", line 1948, in full_dispatch_request
    rv = self.preprocess_request()
  File "/home/ashutosh.mahawar/.local/lib/python3.8/site-packages/flask/app.py", line 2242, in preprocess_request
    rv = func()
  File "/home/ashutosh.mahawar/flaskprojects/application1/app/routes.py", line 74, in before_request
    if current_user.is_authenticated:
  File "/home/ashutosh.mahawar/.local/lib/python3.8/site-packages/werkzeug/local.py", line 347, in __getattr__
    return getattr(self._get_current_object(), name)
  File "/home/ashutosh.mahawar/.local/lib/python3.8/site-packages/werkzeug/local.py", line 306, in _get_current_object
    return self.__local()
  File "/home/ashutosh.mahawar/.local/lib/python3.8/site-packages/flask_login/utils.py", line 26, in <lambda>
    current_user = LocalProxy(lambda: _get_user())
  File "/home/ashutosh.mahawar/.local/lib/python3.8/site-packages/flask_login/utils.py", line 346, in _get_user
    current_app.login_manager._load_user()
  File "/home/ashutosh.mahawar/.local/lib/python3.8/site-packages/flask_login/login_manager.py", line 318, in _load_user
    user = self._user_callback(user_id)
  File "/home/ashutosh.mahawar/flaskprojects/application1/app/models.py", line 73, in load_user
    return User.query.get(int(id))
  File "/home/ashutosh.mahawar/.local/lib/python3.8/site-packages/sqlalchemy/orm/query.py", line 1018, in get
    return self._get_impl(ident, loading.load_on_pk_identity)
  File "/home/ashutosh.mahawar/.local/lib/python3.8/site-packages/sqlalchemy/orm/query.py", line 1135, in _get_impl
    return db_load_fn(self, primary_key_identity)
  File "/home/ashutosh.mahawar/.local/lib/python3.8/site-packages/sqlalchemy/orm/loading.py", line 286, in load_on_pk_identity
    return q.one()
  File "/home/ashutosh.mahawar/.local/lib/python3.8/site-packages/sqlalchemy/orm/query.py", line 3490, in one
    ret = self.one_or_none()
  File "/home/ashutosh.mahawar/.local/lib/python3.8/site-packages/sqlalchemy/orm/query.py", line 3459, in one_or_none
    ret = list(self)
  File "/home/ashutosh.mahawar/.local/lib/python3.8/site-packages/sqlalchemy/orm/query.py", line 3535, in __iter__
    return self._execute_and_instances(context)
  File "/home/ashutosh.mahawar/.local/lib/python3.8/site-packages/sqlalchemy/orm/query.py", line 3556, in _execute_and_instances
    conn = self._get_bind_args(
  File "/home/ashutosh.mahawar/.local/lib/python3.8/site-packages/sqlalchemy/orm/query.py", line 3571, in _get_bind_args
    return fn(
  File "/home/ashutosh.mahawar/.local/lib/python3.8/site-packages/sqlalchemy/orm/query.py", line 3550, in _connection_from_session
    conn = self.session.connection(**kw)
  File "/home/ashutosh.mahawar/.local/lib/python3.8/site-packages/sqlalchemy/orm/session.py", line 1142, in connection
    return self._connection_for_bind(
  File "/home/ashutosh.mahawar/.local/lib/python3.8/site-packages/sqlalchemy/orm/session.py", line 1150, in _connection_for_bind
    return self.transaction._connection_for_bind(
  File "/home/ashutosh.mahawar/.local/lib/python3.8/site-packages/sqlalchemy/orm/session.py", line 433, in _connection_for_bind
    conn = bind._contextual_connect()
  File "/home/ashutosh.mahawar/.local/lib/python3.8/site-packages/sqlalchemy/engine/base.py", line 2302, in _contextual_connect
    self._wrap_pool_connect(self.pool.connect, None),
  File "/home/ashutosh.mahawar/.local/lib/python3.8/site-packages/sqlalchemy/engine/base.py", line 2339, in _wrap_pool_connect
    Connection._handle_dbapi_exception_noconnection(
  File "/home/ashutosh.mahawar/.local/lib/python3.8/site-packages/sqlalchemy/engine/base.py", line 1583, in _handle_dbapi_exception_noconnection
    util.raise_(
  File "/home/ashutosh.mahawar/.local/lib/python3.8/site-packages/sqlalchemy/util/compat.py", line 182, in raise_
    raise exception
  File "/home/ashutosh.mahawar/.local/lib/python3.8/site-packages/sqlalchemy/engine/base.py", line 2336, in _wrap_pool_connect
    return fn()
  File "/home/ashutosh.mahawar/.local/lib/python3.8/site-packages/sqlalchemy/pool/base.py", line 364, in connect
    return _ConnectionFairy._checkout(self)
  File "/home/ashutosh.mahawar/.local/lib/python3.8/site-packages/sqlalchemy/pool/base.py", line 778, in _checkout
    fairy = _ConnectionRecord.checkout(pool)
  File "/home/ashutosh.mahawar/.local/lib/python3.8/site-packages/sqlalchemy/pool/base.py", line 495, in checkout
    rec = pool._do_get()
  File "/home/ashutosh.mahawar/.local/lib/python3.8/site-packages/sqlalchemy/pool/impl.py", line 140, in _do_get
    self._dec_overflow()
  File "/home/ashutosh.mahawar/.local/lib/python3.8/site-packages/sqlalchemy/util/langhelpers.py", line 68, in __exit__
    compat.raise_(
  File "/home/ashutosh.mahawar/.local/lib/python3.8/site-packages/sqlalchemy/util/compat.py", line 182, in raise_
    raise exception
  File "/home/ashutosh.mahawar/.local/lib/python3.8/site-packages/sqlalchemy/pool/impl.py", line 137, in _do_get
    return self._create_connection()
  File "/home/ashutosh.mahawar/.local/lib/python3.8/site-packages/sqlalchemy/pool/base.py", line 309, in _create_connection
    return _ConnectionRecord(self)
  File "/home/ashutosh.mahawar/.local/lib/python3.8/site-packages/sqlalchemy/pool/base.py", line 440, in __init__
    self.__connect(first_connect_check=True)
  File "/home/ashutosh.mahawar/.local/lib/python3.8/site-packages/sqlalchemy/pool/base.py", line 661, in __connect
    pool.logger.debug("Error on connect(): %s", e)
  File "/home/ashutosh.mahawar/.local/lib/python3.8/site-packages/sqlalchemy/util/langhelpers.py", line 68, in __exit__
    compat.raise_(
  File "/home/ashutosh.mahawar/.local/lib/python3.8/site-packages/sqlalchemy/util/compat.py", line 182, in raise_
    raise exception
  File "/home/ashutosh.mahawar/.local/lib/python3.8/site-packages/sqlalchemy/pool/base.py", line 656, in __connect
    connection = pool._invoke_creator(self)
  File "/home/ashutosh.mahawar/.local/lib/python3.8/site-packages/sqlalchemy/engine/strategies.py", line 114, in connect
    return dialect.connect(*cargs, **cparams)
  File "/home/ashutosh.mahawar/.local/lib/python3.8/site-packages/sqlalchemy/engine/default.py", line 508, in connect
    return self.dbapi.connect(*cargs, **cparams)
  File "/home/ashutosh.mahawar/.local/lib/python3.8/site-packages/psycopg2/__init__.py", line 127, in connect
    conn = _connect(dsn, connection_factory=connection_factory, **kwasync)
sqlalchemy.exc.OperationalError: (psycopg2.OperationalError) FATAL:  password authentication failed for user "postgres"
FATAL:  password authentication failed for user "postgres"

(Background on this error at: http://sqlalche.me/e/13/e3q8)
